Workbook

Sheet zestawienie
A1: stacja | B1: ilość | C1: długość
A2: 05-0112 | B2: =COUNTA('05-0112'!A:A)-1 -> 16 | C2: =SUM('05-0112'!D:D) -> 618
A3: 05-0115 | B3: =COUNTA('05-0115'!A:A)-1 -> 4 | C3: =SUM('05-0115'!D:D) -> 125
A4: 05-0181 | B4: =COUNTA('05-0181'!A:A)-1 -> 33 | C4: =SUM('05-0181'!D:D) -> 1307
A5: 05-0191 | B5: =COUNTA('05-0191'!A:A)-1 -> 8 | C5: =SUM('05-0191'!D:D) -> 350
A6: 05-0195 | B6: =COUNTA('05-0195'!A:A)-1 -> 34 | C6: =SUM('05-0195'!D:D) -> 1527
A7: 05-0355 | B7: =COUNTA('05-0355'!A:A)-1 -> 28 | C7: =SUM('05-0355'!D:D) -> 1041
A8: 05-0398 | B8: =COUNTA('05-0398'!A:A)-1 -> 24 | C8: =SUM('05-0398'!D:D) -> 1006
A9: 05-0739 | B9: =COUNTA('05-0739'!A:A)-1 -> 29 | C9: =SUM('05-0739'!D:D) -> 1317
A10: 05-0885 | B10: =COUNTA('05-0885'!A:A)-1 -> 23 | C10: =SUM('05-0885'!D:D) -> 957
A11: 05-0917 | B11: =COUNTA('05-0917'!A:A)-1 -> 16 | C11: =SUM('05-0917'!D:D) -> 681
A12: 05-0918 | B12: =COUNTA('05-0918'!A:A)-1 -> 49 | C12: =SUM('05-0918'!D:D) -> 1778
A13: 05-1067 | B13: =COUNTA('05-1067'!A:A)-1 -> 20 | C13: =SUM('05-1067'!D:D) -> 796
A14: 05-1069 | B14: =COUNTA('05-1069'!A:A)-1 -> 37 | C14: =SUM('05-1069'!D:D) -> 1082
A15: RAZEM | B15: =SUM(B2:B14) -> 321 | C15: =SUM(C2:C14) -> 12585

Sheet 05-0112
A1: Nr słupa | B1: Oznaczenie | C1: Typ | D1: Odległość | E1: Mufa | F1: Obwód
A2: 1 | B2: P | C2: -10/ZN | D2: 20 | F2: 1
A3: 2 | B3: RPKr | C3: -10/ZN | D3: 19 | E3: 1 | F3: 1
A4: 3 | B4: P | C4: -10/ZN | D4: 33 | F4: 1
A5: 4 | B5: P | C5: -10/ZN | D5: 38 | F5: 1
A6: 5 | B6: P | C6: -10/ZN | D6: 47 | E6: 1 | F6: 1
A7: 6 | B7: P | C7: -10/ZN | D7: 43 | F7: 1
A8: 7 | B8: P | C8: -10/ZN | D8: 44 | F8: 1
A9: 8 | B9: P | C9: -10/ZN | D9: 50 | E9: 1 | F9: 1
A10: 9 | B10: P | C10: -10/ZN | D10: 49 | F10: 1
A11: 10 | B11: P | C11: -10/ZN | D11: 50 | F11: 1
A12: 11 | B12: Kb | C12: -10/ZN | D12: 49 | E12: 1 | F12: 1
A13: 1 | B13: P | C13: -10/ZN | D13: 16 | F13: 2
A14: 2 | B14: P | C14: -10/ZN | D14: 16 | F14: 2
A15: 3 | B15: RPKr | C15: -10/ZN | D15: 34 | E15: 1 | F15: 2
A16: 4 | B16: P | C16: -10/ZN | D16: 55 | F16: 2
A17: 5 | B17: Nr | C17: -10/ZN | D17: 55 | E17: 1 | F17: 2

Sheet 05-0115
A1: Nr słupa | B1: Oznaczenie | C1: Typ | D1: Odległość | E1: Mufa | F1: Obwód
A2: 1 | B2: RPKb | C2: -10/ZN | D2: 22 | E2: 1 | F2: 1
A3: 2 | B3: P | C3: -10/ZN | D3: 21 | F3: 1
A4: 3 | B4: P | C4: -10/ZN | D4: 37 | F4: 1
A5: 4 | B5: Kr | C5: -10/ZN | D5: 45 | E5: 1 | F5: 1

Sheet 05-0181
A1: Nr słupa | B1: Oznaczenie | C1: Typ | D1: Odległość | E1: Mufa | F1: Obwód
A2: 1 | B2: Nr | C2: -10/ZN | D2: 37 | E2: 1 | F2: 1
A3: 2 | B3: P | C3: -10/ZN | D3: 32 | F3: 1
A4: 3 | B4: RPKr | C4: -10/ZN | D4: 46 | F4: 1
A5: 4 | B5: RPKr | C5: -10/ZN | D5: 35 | E5: 1 | F5: 1
A6: 4.1 | B6: P | C6: -10/ZN | D6: 47 | F6: 1
A7: 4.2 | B7: P | C7: -10/ZN | D7: 47 | E7: 1 | F7: 1
A8: 4.2.1 | B8: P | C8: -10/ZN | D8: 30 | F8: 1
A9: 4.3 | B9: P | C9: -10/ZN | D9: 41 | F9: 1
A10: 4.4 | B10: Kr | C10: -10/ZN | D10: 39 | E10: 1 | F10: 1
A11: 5 | B11: P | C11: -10/ZN | D11: 54 | F11: 1
A12: 6 | B12: P | C12: -10/ZN | D12: 45 | E12: 1 | F12: 1
A13: 7 | B13: P | C13: -10/ZN | D13: 44 | F13: 1
A14: 8 | B14: P | C14: -10/ZN | D14: 36 | F14: 1
A15: 9 | B15: RPKr | C15: -10/ZN | D15: 29 | E15: 1 | F15: 1
A16: 9.1 | B16: Nr | C16: -10/ZN | D16: 49 | F16: 1
A17: 9.2 | B17: Kr | C17: -10/ZN | D17: 28 | F17: 1
A18: 10 | B18: RPKr | C18: -10/ZN | D18: 44 | F18: 1
A19: 11 | B19: P | C19: -10/ZN | D19: 34 | F19: 1
A20: 12 | B20: N | C20: -10.5/10/E | D20: 33 | E20: 1 | F20: 1
A21: 13 | B21: P | C21: -10/ZN | D21: 45 | F21: 1
A22: 14 | B22: K | C22: -10.5/10/E | D22: 46 | F22: 1
A23: 1 | B23: Nr | C23: -10/ZN | D23: 37 | F23: 2
A24: 2 | B24: P | C24: -10/ZN | D24: 44 | F24: 2
A25: 3 | B25: P | C25: -10/ZN | D25: 32 | E25: 1 | F25: 2
A26: 4 | B26: P | C26: -10/ZN | D26: 39 | F26: 2
A27: 5 | B27: P | C27: -10/ZN | D27: 33 | F27: 2
A28: 6 | B28: RPKb | C28: -10/ZN | D28: 33 | E28: 1 | F28: 2
A29: 6.1 | B29: P | C29: -10/ZN | D29: 29 | F29: 2
A30: 7 | B30: P | C30: -10/ZN | D30: 49 | E30: 1 | F30: 2
A31: 7.1 | B31: P | C31: -10/ZN | D31: 41 | F31: 2
A32: 7.2 | B32: P | C32: -10/ZN | D32: 39 | F32: 2
A33: 7.3 | B33: Kr | C33: -10/ZN | D33: 38 | E33: 1 | F33: 2
A34: 8 | B34: K | C34: -10.5/10/E | D34: 52 | F34: 2

Sheet 05-0191
A1: Nr słupa | B1: Oznaczenie | C1: Typ | D1: Odległość | E1: Mufa | F1: Obwód
A2: 1 | B2: P | C2: -10/ZN | D2: 25 | E2: 1 | F2: 1
A3: 2 | B3: P | C3: -10/ZN | D3: 25 | F3: 1
A4: 3 | B4: P | C4: -10/ZN | D4: 53 | F4: 1
A5: 4 | B5: RPKr | C5: -10/ZN | D5: 49 | F5: 1
A6: 5 | B6: P | C6: -10/ZN | D6: 48 | E6: 1 | F6: 1
A7: 6 | B7: P | C7: -10/ZN | D7: 50 | F7: 1
A8: 7 | B8: P | C8: -10/ZN | D8: 51 | F8: 1
A9: 8 | B9: P | C9: -10/ZN | D9: 49 | E9: 1 | F9: 1

Sheet 05-0195
A1: Nr słupa | B1: Oznaczenie | C1: Typ | D1: Odległość | E1: Mufa | F1: Obwód
A2: 1 | B2: P | C2: -10/ZN | D2: 47 | F2: 1
A3: 2 | B3: RPK | C3: -10.5/10/E | D3: 24 | F3: 1
A4: 3 | B4: P | C4: -10/ZN | D4: 22 | E4: 1 | F4: 1
A5: 4 | B5: P | C5: -10/ZN | D5: 42 | F5: 1
A6: 5 | B6: Nr | C6: -10/ZN | D6: 46 | F6: 1
A7: 6 | B7: P | C7: -10/ZN | D7: 49 | E7: 1 | F7: 1
A8: 7 | B8: RPKr | C8: -10/ZN | D8: 37 | F8: 1
A9: 8 | B9: P | C9: -10/ZN | D9: 50 | F9: 1
A10: 9 | B10: P | C10: -10/ZN | D10: 50 | E10: 1 | F10: 1
A11: 10 | B11: RPKr | C11: -10/ZN | D11: 47 | F11: 1
A12: 11 | B12: P | C12: -10/ZN | D12: 41 | F12: 1
A13: 12 | B13: P | C13: -10/ZN | D13: 45 | E13: 1 | F13: 1
A14: 13 | B14: RPKr | C14: -10/ZN | D14: 48 | F14: 1
A15: 14 | B15: P | C15: -10/ZN | D15: 43 | F15: 1
A16: 15 | B16: N | C16: -10.5/10/E | D16: 44 | E16: 1 | F16: 1
A17: 16 | B17: P | C17: -10/ZN | D17: 39 | F17: 1
A18: 17 | B18: RPKr | C18: -10/ZN | D18: 37 | F18: 1
A19: 18 | B19: Kr | C19: -10/ZN | D19: 45 | E19: 1 | F19: 1
A20: 1 | B20: P | C20: -10/ZN | D20: 47 | E20: 1 | F20: 2
A21: 2 | B21: P | C21: -10/ZN | D21: 48 | F21: 2
A22: 3 | B22: P | C22: -10/ZN | D22: 41 | F22: 2
A23: 4 | B23: RPKr | C23: -10/ZN | D23: 34 | E23: 1 | F23: 2
A24: 5 | B24: Nr | C24: -10/ZN | D24: 47 | F24: 2
A25: 6 | B25: P | C25: -10/ZN | D25: 50 | F25: 2
A26: 7 | B26: P | C26: -10/ZN | D26: 50 | E26: 1 | F26: 2
A27: 8 | B27: P | C27: -10/ZN | D27: 53 | F27: 2
A28: 9 | B28: P | C28: -10/ZN | D28: 51 | F28: 2
A29: 10 | B29: P | C29: -10/ZN | D29: 52 | E29: 1 | F29: 2
A30: 11 | B30: P | C30: -10/ZN | D30: 51 | F30: 2
A31: 12 | B31: P | C31: -10/ZN | D31: 49 | F31: 2
A32: 13 | B32: P | C32: -10/ZN | D32: 53 | E32: 1 | F32: 2
A33: 14 | B33: P | C33: -10/ZN | D33: 53 | F33: 2
A34: 15 | B34: RPKr | C34: -10/ZN | D34: 55 | E34: 1 | F34: 2
A35: 16 | B35: Kr | C35: -10/ZN | D35: 37 | F35: 2

Sheet 05-0355
A1: Nr słupa | B1: Oznaczenie | C1: Typ | D1: Odległość | E1: Mufa | F1: Obwód
A2: 1 | B2: P | C2: -10/ZN | D2: 8 | F2: 1
A3: 2 | B3: P | C3: -10/ZN | D3: 8 | F3: 1
A4: 3 | B4: P | C4: -10/ZN | D4: 50 | E4: 1 | F4: 1
A5: 4 | B5: P | C5: -10/ZN | D5: 27 | F5: 1
A6: 5 | B6: P | C6: -10/ZN | D6: 25 | F6: 1
A7: 6 | B7: Nr | C7: -10/ZN | D7: 49 | E7: 1 | F7: 1
A8: 7 | B8: P | C8: -10/ZN | D8: 30 | F8: 1
A9: 8 | B9: P | C9: -10/ZN | D9: 17 | F9: 1
A10: 9 | B10: Nr | C10: -10/ZN | D10: 46 | E10: 1 | F10: 1
A11: 10 | B11: P | C11: -10/ZN | D11: 54 | F11: 1
A12: 1 | B12: Nr | C12: -10/ZN | D12: 23 | E12: 1 | F12: 2
A13: 2 | B13: P | C13: -10/ZN | D13: 23 | F13: 2
A14: 3 | B14: P | C14: -10/ZN | D14: 23 | F14: 2
A15: 4 | B15: P | C15: -10/ZN | D15: 25 | E15: 1 | F15: 2
A16: 5 | B16: P | C16: -10/ZN | D16: 54 | F16: 2
A17: 6 | B17: P | C17: -10/ZN | D17: 50 | F17: 2
A18: 7 | B18: P | C18: -10/ZN | D18: 49 | E18: 1 | F18: 2
A19: 7.1 | B19: N | C19: -10.5/10/E | D19: 16 | F19: 2
A20: 7.2 | B20: Nr | C20: -10/ZN | D20: 41 | F20: 2
A21: 7.3 | B21: N | C21: -10.5/10/E | D21: 35 | F21: 2
A22: 8 | B22: P | C22: -10/ZN | D22: 46 | F22: 2
A23: 9 | B23: P | C23: -10/ZN | D23: 58 | F23: 2
A24: 10 | B24: P | C24: -10/ZN | D24: 46 | E24: 1 | F24: 2
A25: 11 | B25: P | C25: -10/ZN | D25: 53 | F25: 2
A26: 12 | B26: P | C26: -10/ZN | D26: 39 | F26: 2
A27: 13 | B27: Nr | C27: -10/ZN | D27: 52 | E27: 1 | F27: 2
A28: 14 | B28: P | C28: -10/ZN | D28: 46 | F28: 2
A29: 15 | B29: Kr | C29: -10/ZN | D29: 48 | E29: 1 | F29: 2

Sheet 05-0398
A1: Nr słupa | B1: Oznaczenie | C1: Typ | D1: Odległość | E1: Mufa | F1: Obwód
A2: 1 | B2: K | C2: -10.5/10/E | D2: 21 | E2: 1 | F2: 1
A3: 2 | B3: P | C3: -10/ZN | D3: 21 | F3: 1
A4: 3 | B4: P | C4: -10/ZN | D4: 21 | F4: 1
A5: 4 | B5: P | C5: -10/ZN | D5: 32 | F5: 1
A6: 5 | B6: P | C6: -10/ZN | D6: 51 | E6: 1 | F6: 1
A7: 6 | B7: P | C7: -10/ZN | D7: 51 | F7: 1
A8: 7 | B8: P | C8: -10/ZN | D8: 50 | F8: 1
A9: 8 | B9: P | C9: -10/ZN | D9: 46 | E9: 1 | F9: 1
A10: 9 | B10: P | C10: -10/ZN | D10: 50 | F10: 1
A11: 10 | B11: P | C11: -10/ZN | D11: 58 | F11: 1
A12: 11 | B12: P | C12: -10/ZN | D12: 35 | E12: 1 | F12: 1
A13: 12 | B13: P | C13: -10/ZN | D13: 38 | F13: 1
A14: 13 | B14: P | C14: -10/ZN | D14: 32 | F14: 1
A15: 14 | B15: P | C15: -10/ZN | D15: 45 | E15: 1 | F15: 1
A16: 15 | B16: P | C16: -10/ZN | D16: 23 | F16: 1
A17: 16 | B17: P | C17: -10/ZN | D17: 45 | F17: 1
A18: 17 | B18: P | C18: -10/ZN | D18: 63 | E18: 1 | F18: 1
A19: 18 | B19: P | C19: -10/ZN | D19: 50 | F19: 1
A20: 19 | B20: P | C20: -10/ZN | D20: 50 | F20: 1
A21: 20 | B21: P | C21: -10/ZN | D21: 40 | E21: 1 | F21: 1
A22: 21 | B22: P | C22: -10/ZN | D22: 47 | F22: 1
A23: 22 | B23: P | C23: -10/ZN | D23: 48 | F23: 1
A24: 23 | B24: P | C24: -10/ZN | D24: 47 | F24: 1
A25: 24 | B25: P | C25: -10/ZN | D25: 42 | E25: 1 | F25: 1

Sheet 05-0739
A1: Nr słupa | B1: Oznaczenie | C1: Typ | D1: Odległość | E1: Mufa | F1: Obwód
A2: 1 | B2: RPKr | C2: -10/ZN | D2: 31 | F2: 1
A3: 2 | B3: P | C3: -10/ZN | D3: 45 | F3: 1
A4: 3 | B4: P | C4: -10/ZN | D4: 50 | F4: 1
A5: 4 | B5: P | C5: -10/ZN | D5: 49 | E5: 1 | F5: 1
A6: 5 | B6: P | C6: -10/ZN | D6: 49 | F6: 1
A7: 6 | B7: P | C7: -10/ZN | D7: 49 | F7: 1
A8: 7 | B8: Nr | C8: -10/ZN | D8: 49 | E8: 1 | F8: 1
A9: 8 | B9: P | C9: -10/ZN | D9: 50 | F9: 1
A10: 9 | B10: RPKr | C10: -10/ZN | D10: 48 | F10: 1
A11: 10 | B11: P | C11: -10/ZN | D11: 50 | E11: 1 | F11: 1
A12: 11 | B12: Nr | C12: -10/ZN | D12: 50 | F12: 1
A13: 12 | B13: Nr | C13: -10/ZN | D13: 49 | F13: 1
A14: 13 | B14: RPKr | C14: -10/ZN | D14: 51 | E14: 1 | F14: 1
A15: 13.1 | B15: Kr | C15: -10/ZN | D15: 46 | F15: 1
A16: 14 | B16: P | C16: -10/ZN | D16: 45 | F16: 1
A17: 15 | B17: RPKr | C17: -10/ZN | D17: 53 | F17: 1
A18: 16 | B18: P | C18: -10/ZN | D18: 49 | E18: 1 | F18: 1
A19: 17 | B19: P | C19: -10/ZN | D19: 49 | F19: 1
A20: 18 | B20: P | C20: -10/ZN | D20: 50 | F20: 1
A21: 19 | B21: RPKr | C21: -10/ZN | D21: 50 | E21: 1 | F21: 1
A22: 20 | B22: Nr | C22: -10/ZN | D22: 50 | F22: 1
A23: 21 | B23: P | C23: -10/ZN | D23: 44 | F23: 1
A24: 22 | B24: Kr | C24: -10/ZN | D24: 24 | E24: 1 | F24: 1
A25: 1 | B25: N | C25: -10.5/10/E | D25: 30 | E25: 1 | F25: 2
A26: 2 | B26: N | C26: -10.5/10/E | D26: 38 | F26: 2
A27: 3 | B27: N | C27: -10.5/10/E | D27: 43 | F27: 2
A28: 4 | B28: N | C28: -10.5/10/E | D28: 21 | E28: 1 | F28: 2
A29: 5 | B29: P | C29: -10/ZN | D29: 47 | F29: 2
A30: 6 | B30: P | C30: -10/ZN | D30: 58 | E30: 1 | F30: 2

Sheet 05-0885
A1: Nr słupa | B1: Oznaczenie | C1: Typ | D1: Odległość | E1: Mufa | F1: Obwód
A2: 1 | B2: P | C2: -10/ZN | D2: 21 | E2: 1 | F2: 1
A3: 2 | B3: P | C3: -10/ZN | D3: 20 | F3: 1
A4: 3 | B4: P | C4: -10/ZN | D4: 45 | F4: 1
A5: 4 | B5: P | C5: -10/ZN | D5: 47 | E5: 1 | F5: 1
A6: 5 | B6: P | C6: -10/ZN | D6: 51 | F6: 1
A7: 6 | B7: P | C7: -10/ZN | D7: 52 | F7: 1
A8: 7 | B8: P | C8: -10/ZN | D8: 44 | E8: 1 | F8: 1
A9: 7.1 | B9: P | C9: -10/ZN | D9: 31 | F9: 1
A10: 8 | B10: P | C10: -10/ZN | D10: 48 | E10: 1 | F10: 1
A11: 8.1 | B11: P | C11: -10/ZN | D11: 27 | F11: 1
A12: 9 | B12: RPKr | C12: -10/ZN | D12: 52 | E12: 1 | F12: 1
A13: 9.1 | B13: P | C13: -10/ZN | D13: 36 | F13: 1
A14: 10 | B14: P | C14: -10/ZN | D14: 41 | F14: 1
A15: 11 | B15: P | C15: -10/ZN | D15: 41 | F15: 1
A16: 12 | B16: P | C16: -10/ZN | D16: 44 | E16: 1 | F16: 1
A17: 13 | B17: P | C17: -10/ZN | D17: 45 | F17: 1
A18: 14 | B18: N | C18: -10.5/10/E | D18: 53 | E18: 1 | F18: 1
A19: 15 | B19: P | C19: -10/ZN | D19: 51 | F19: 1
A20: 16 | B20: P | C20: -10/ZN | D20: 46 | E20: 1 | F20: 1
A21: 17 | B21: P | C21: -10/ZN | D21: 42 | F21: 1
A22: 18 | B22: Nr | C22: -10/ZN | D22: 38 | E22: 1 | F22: 1
A23: 19 | B23: Nr | C23: -10/ZN | D23: 48 | F23: 1
A24: 20 | B24: P | C24: -10/ZN | D24: 34 | E24: 1 | F24: 1

Sheet 05-0917
A1: Nr słupa | B1: Oznaczenie | C1: Typ | D1: Odległość | E1: Mufa | F1: Obwód
A2: 1 | B2: P | C2: -10/ZN | D2: 42 | F2: 1
A3: 2 | B3: P | C3: -10/ZN | D3: 28 | E3: 1 | F3: 1
A4: 3 | B4: P | C4: -10/ZN | D4: 45 | F4: 1
A5: 4 | B5: P | C5: -10/ZN | D5: 47 | F5: 1
A6: 5 | B6: RPK | C6: -10.5/10/E | D6: 46 | E6: 1 | F6: 1
A7: 5.1 | B7: Nr | C7: -10/ZN | D7: 41 | F7: 1
A8: 5.2 | B8: K | C8: -10.5/10/E | D8: 37 | F8: 1
A9: 6 | B9: Kr | C9: -10/ZN | D9: 83 | F9: 1
A10: 1 | B10: P | C10: -10/ZN | D10: 41 | F10: 2
A11: 2 | B11: P | C11: -10/ZN | D11: 47 | F11: 2
A12: 3 | B12: P | C12: -10/ZN | D12: 18 | E12: 1 | F12: 2
A13: 3.1 | B13: Nr | C13: -10/ZN | D13: 34 | F13: 2
A14: 3.2 | B14: Kr | C14: -10/ZN | D14: 47 | F14: 2
A15: 4 | B15: P | C15: -10/ZN | D15: 31 | F15: 2
A16: 5 | B16: RPK | C16: -10.5/10/E | D16: 53 | F16: 2
A17: 6 | B17: Kr | C17: -10/ZN | D17: 41 | F17: 2

Sheet 05-0918
A1: Nr słupa | B1: Oznaczenie | C1: Typ | D1: Odległość | E1: Mufa | F1: Obwód
A2: 1 | B2: RPKr | C2: -10/ZN | D2: 27 | F2: 1
A3: 2 | B3: RPKr | C3: -10/ZN | D3: 52 | E3: 1 | F3: 1
A4: 2.1 | B4: Nr | C4: -10/ZN | D4: 33 | F4: 1
A5: 2.2 | B5: P | C5: -10/ZN | D5: 45 | F5: 1
A6: 2.3 | B6: P | C6: -10/ZN | D6: 31 | E6: 1 | F6: 1
A7: 2.4 | B7: P | C7: -10/ZN | D7: 45 | F7: 1
A8: 2.5 | B8: P | C8: -10/ZN | D8: 49 | E8: 1 | F8: 1
A9: 2.6 | B9: P | C9: -10/ZN | D9: 33 | F9: 1
A10: 2.7 | B10: Nr | C10: -10/ZN | D10: 44 | F10: 1
A11: 2.8 | B11: P | C11: -10/ZN | D11: 27 | F11: 1
A12: 3 | B12: P | C12: -10/ZN | D12: 35 | F12: 1
A13: 4 | B13: P | C13: -10/ZN | D13: 39 | E13: 1 | F13: 1
A14: 5 | B14: P | C14: -10/ZN | D14: 59 | F14: 1
A15: 6 | B15: P | C15: -10/ZN | D15: 63 | F15: 1
A16: 7 | B16: Kr | C16: -10/ZN | D16: 22 | E16: 1 | F16: 1
A17: 1 | B17: Nr | C17: -10/ZN | D17: 22 | F17: 2
A18: 2 | B18: P | C18: -10/ZN | D18: 22 | F18: 2
A19: 3 | B19: P | C19: -10/ZN | D19: 43 | F19: 2
A20: 4 | B20: P | C20: -10/ZN | D20: 38 | F20: 2
A21: 5 | B21: P | C21: -10/ZN | D21: 46 | E21: 1 | F21: 2
A22: 6 | B22: P | C22: -10/ZN | D22: 23 | F22: 2
A23: 7 | B23: P | C23: -10/ZN | D23: 31 | F23: 2
A24: 8 | B24: RPKb | C24: -10/ZN | D24: 29 | E24: 1 | F24: 2
A25: 8.1 | B25: Nr | C25: -10/ZN | D25: 15 | F25: 2
A26: 8.2 | B26: Kr | C26: -10/ZN | D26: 34 | F26: 2
A27: 9 | B27: Kr | C27: -10/ZN | D27: 54 | F27: 2
A28: 10 | B28: Kr | C28: -10/ZN | D28: 72 | F28: 2
A29: 11 | B29: RPKr | C29: -10/ZN | D29: 27 | E29: 1 | F29: 2
A30: 12 | B30: P | C30: -10/ZN | D30: 39 | F30: 2
A31: 13 | B31: P | C31: -10/ZN | D31: 38 | F31: 2
A32: 14 | B32: RPKr | C32: -10/ZN | D32: 21 | E32: 1 | F32: 2
A33: 15 | B33: P | C33: -10/ZN | D33: 29 | F33: 2
A34: 15.1 | B34: P | C34: -10/ZN | D34: 39 | F34: 2
A35: 15.2 | B35: Kr | C35: -10/ZN | D35: 38 | F35: 2
A36: 16 | B36: RPKr | C36: -10/ZN | D36: 28 | F36: 2
A37: 17 | B37: Kr | C37: -10/ZN | D37: 19 | E37: 1 | F37: 2
A38: 1 | B38: Kr | C38: -10/ZN | D38: 28 | E38: 1 | F38: 3
A39: 2 | B39: Nr | C39: -10/ZN | D39: 37 | F39: 3
A40: 3 | B40: RPKr | C40: -10/ZN | D40: 33 | E40: 1 | F40: 3
...

Sheet 05-1067
A1: Nr słupa | B1: Oznaczenie | C1: Typ | D1: Odległość | E1: Mufa | F1: Obwód
A2: 1 | B2: P | C2: -10/ZN | D2: 27 | E2: 1 | F2: 1
A3: 2 | B3: RPKr | C3: -10/ZN | D3: 47 | F3: 1
A4: 3 | B4: P | C4: -10/ZN | D4: 39 | F4: 1
A5: 4 | B5: P | C5: -10/ZN | D5: 51 | E5: 1 | F5: 1
A6: 5 | B6: Or | C6: -10/ZN | D6: 53 | F6: 1
A7: 6 | B7: P | C7: -10/ZN | D7: 41 | F7: 1
A8: 7 | B8: P | C8: -10/ZN | D8: 40 | E8: 1 | F8: 1
A9: 8 | B9: P | C9: -10/ZN | D9: 30 | F9: 1
A10: 9 | B10: RPKr | C10: -10/ZN | D10: 40 | F10: 1
A11: 10 | B11: Nr | C11: -10/ZN | D11: 18 | E11: 1 | F11: 1
A12: 12 | B12: Kr | C12: -10/ZN | D12: 27 | F12: 1
A13: 1 | B13: Or | C13: -10/ZN | D13: 27 | F13: 2
A14: 2 | B14: RPKr | C14: -10/ZN | D14: 41 | F14: 2
A15: 3 | B15: RPKr | C15: -10/ZN | D15: 37 | E15: 1 | F15: 2
A16: 3.1 | B16: P | C16: -10/ZN | D16: 54 | F16: 2
A17: 3.2 | B17: P | C17: -10/ZN | D17: 49 | F17: 2
A18: 3.3 | B18: Kr | C18: -10/ZN | D18: 46 | E18: 1 | F18: 2
A19: 4 | B19: P | C19: -10/ZN | D19: 36 | F19: 2
A20: 5 | B20: Nr | C20: -10/ZN | D20: 53 | F20: 2
A21: 6 | B21: Kr | C21: -10/ZN | D21: 40 | F21: 2

Sheet 05-1069
A1: Nr słupa | B1: Oznaczenie | C1: Typ | D1: Odległość | E1: Mufa | F1: Obwód
A2: 1 | B2: Nr | C2: -10/ZN | D2: 20 | F2: 1
A3: 2 | B3: P | C3: -10/ZN | D3: 23 | F3: 1
A4: 3 | B4: P | C4: -10/ZN | D4: 21 | E4: 1 | F4: 1
A5: 4 | B5: P | C5: -10/ZN | D5: 25 | F5: 1
A6: 5 | B6: P | C6: -10/ZN | D6: 25 | F6: 1
A7: 6 | B7: P | C7: -10/ZN | D7: 22 | E7: 1 | F7: 1
A8: 7 | B8: P | C8: -10/ZN | D8: 25 | F8: 1
A9: 8 | B9: P | C9: -10/ZN | D9: 18 | F9: 1
A10: 9 | B10: P | C10: -10/ZN | D10: 24 | F10: 1
A11: 10 | B11: RPKr | C11: -10/ZN | D11: 18 | E11: 1 | F11: 1
A12: 10.1 | B12: P | C12: -10/ZN | D12: 49 | F12: 1
A13: 10.2 | B13: P | C13: -10/ZN | D13: 55 | F13: 1
A14: 10.3 | B14: P | C14: -10/ZN | D14: 33 | E14: 1 | F14: 1
A15: 10.4 | B15: RPKr | C15: -10/ZN | D15: 26 | F15: 1
A16: 10.5 | B16: N | C16: -10.5/10/E | D16: 6 | F16: 1
A17: 10.6 | B17: P | C17: -10/ZN | D17: 41 | F17: 1
A18: 10.7 | B18: K | C18: -10.5/10/E | D18: 46 | E18: 1 | F18: 1
A19: 11 | B19: P | C19: -10/ZN | D19: 20 | F19: 1
A20: 12 | B20: P | C20: -10/ZN | D20: 28 | F20: 1
A21: 13 | B21: P | C21: -10/ZN | D21: 40 | F21: 1
A22: 14 | B22: P | C22: -10/ZN | D22: 23 | E22: 1 | F22: 1
A23: 15 | B23: P | C23: -10/ZN | D23: 24 | F23: 1
A24: 16 | B24: RPKr | C24: -10/ZN | D24: 22 | F24: 1
A25: 17 | B25: P | C25: -10/ZN | D25: 30 | E25: 1 | F25: 1
A26: 18 | B26: P | C26: -10/ZN | D26: 36 | F26: 1
A27: 19 | B27: P | C27: -10/ZN | D27: 30 | F27: 1
A28: 20 | B28: Kr | C28: -10/ZN | D28: 25 | E28: 1 | F28: 1
A29: 1 | B29: Nr | C29: -10/ZN | D29: 20 | F29: 2
A30: 2 | B30: P | C30: -10/ZN | D30: 29 | E30: 1 | F30: 2
A31: 3 | B31: P | C31: -10/ZN | D31: 42 | F31: 2
A32: 4 | B32: P | C32: -10/ZN | D32: 48 | E32: 1 | F32: 2
A33: 5 | B33: P | C33: -10/ZN | D33: 46 | F33: 2
A34: 6 | B34: P | C34: -10/ZN | D34: 26 | E34: 1 | F34: 2
A35: 7 | B35: P | C35: -10/ZN | D35: 26 | F35: 2
A36: 8 | B36: P | C36: -10/ZN | D36: 40 | E36: 1 | F36: 2
A37: 8.1 | B37: P | C37: -10/ZN | D37: 22 | F37: 2
A38: 9 | B38: Kr | C38: -10/ZN | D38: 28 | F38: 2

Sheet uwagi
A1: Uwagi do sprawdzenia
A2: Numer "2.4" (319.97, 102.36) nie został przypisany do żadnego słupu.
A3: 4 słup(y) bez numeru poza zakresami stacji (np. legenda) - pominięto.
A4: Stacja 05-0346: 20 słupów bez numerów - pominięto (ponumeruj słupy na rysunku).
A5: Słup nr 24 (7554129.88, 5772735.21): brak wymiaru - odległość zmierzona geometrycznie (42 m).
A6: Stacja 05-1067, obwód 1: jest słup nr 12, a brak słupa nr 11 (luka w numeracji?).
